<?xml version="1.0"?>


<robot name="naive_robot_7_axis">
    <material name="blue">
        <color rgba="0.1 0.1 0.7 1"/>
    </material>

    <material name="gray">
        <color rgba="0.5 0.5 0.5 1"/>
    </material>

    <material name="white">
        <color rgba="1 1 1 1"/>
    </material>

    <link name="base_link">
        <visual>
            <geometry>
                <cylinder length="0.15" radius="0.1"/>
            </geometry>
            <origin rpy="0 0 0" xyz="0 0 0.075"/>
            <material name="gray"/>
        </visual>
        <collision>
            <geometry>
                <cylinder length="0.15" radius="0.1"/>
            </geometry>
            <origin rpy="0 0 0" xyz="0 0 0.075"/>
        </collision>
        <inertial>
            <origin rpy="0 0 0" xyz="0 0 0.075"/>
            <mass value="10"/>
            <inertia ixx="0.01"  ixy="0"  ixz="0" iyy="0.01" iyz="0" izz="0.1" />
        </inertial>

    </link>

    <link name="link_1">
        <visual>
            <geometry>
                <cylinder length="0.20" radius="0.1"/>
            </geometry>
            <origin rpy="0 0 0" xyz="0 0 0.1"/>
            <material name="blue"/>
        </visual>
        <collision>
            <geometry>
                <cylinder length="0.20" radius="0.1"/>
            </geometry>
            <origin rpy="0 0 0" xyz="0 0 0.1"/>
        </collision>
        <inertial>
            <origin rpy="0 0 0" xyz="0 0 0.1"/>
            <mass value="10"/>
            <inertia ixx="0.01"  ixy="0"  ixz="0" iyy="0.01" iyz="0" izz="0.1" />
        </inertial>
    </link>

    <joint name="joint_1" type="revolute">
        <parent link="base_link"/>
        <child link="link_1"/>
        <origin xyz="0 0 0.15" rpy="0.0 0.0 0.0"/>
        <axis xyz="0 0 1"/>
        <limit lower="-3.14" upper="3.14" effort="100.0" velocity="3.14"/>
    </joint>


    <link name="link_2">
        <visual>
            <geometry>
                <cylinder length="0.20" radius="0.075"/>
            </geometry>
            <origin rpy="0 0 0" xyz="0 0.075 0"/>
            <material name="gray"/>
        </visual>
        <collision>
            <geometry>
                <cylinder length="0.20" radius="0.075"/>
            </geometry>
            <origin rpy="0 0 0" xyz="0 0.075 0"/>
        </collision>
        <inertial>
            <origin rpy="0 0 0" xyz="0 0.075 0"/>
            <mass value="10"/>
            <inertia ixx="0.01"  ixy="0"  ixz="0" iyy="0.01" iyz="0" izz="0.1" />
        </inertial>
    </link>


    <joint name="joint_2" type="revolute">
        <parent link="link_1"/>
        <child link="link_2"/>
        <origin xyz="0 0.1 0.1" rpy="0.0 0.0 0.0"/>
        <axis xyz="0 1 0"/>
        <limit lower="-3.14" upper="3.14" effort="100.0" velocity="3.14"/>
    </joint>

    
    <link name="link_3">
        <visual>
            <geometry>
                <cylinder length="0.6" radius="0.075"/>
            </geometry>
            <origin rpy="0 0 0" xyz="0 0 0.3"/>
            <material name="blue"/>
        </visual>
        <collision>
            <geometry>
                <cylinder length="0.6" radius="0.075"/>
            </geometry>
            <origin rpy="0 0 0" xyz="0 0 0.3"/>
        </collision>
        <inertial>
            <origin rpy="0 0 0" xyz="0 0 0.3"/>
            <mass value="10"/>
            <inertia ixx="0.01"  ixy="0"  ixz="0" iyy="0.01" iyz="0" izz="0.1" />
        </inertial>
    </link>


    <joint name="joint3" type="revolute">
        <parent link="link_2"/>
        <child link="link_3"/>
        <origin xyz="0 0.075 0.1" rpy="0.0 0.0 0.0"/>
        <axis xyz="0 0 1"/>
        <limit lower="-3.14" upper="3.14" effort="100.0" velocity="3.14"/>
    </joint>


    <link name="link_4">
        <visual>
            <geometry>
                <cylinder length="0.1" radius="0.05"/>
            </geometry>
            <origin rpy="0 0 0" xyz="0 -0.05 0"/>
            <material name="gray"/>
        </visual>
        <collision>
            <geometry>
                <cylinder length="0.1" radius="0.05"/>
            </geometry>
            <origin rpy="0 0 0" xyz="0 -0.05 0"/>
        </collision>
        <inertial>
            <origin rpy="0 0 0" xyz="0 -0.05 0"/>
            <mass value="10"/>
            <inertia ixx="0.01"  ixy="0"  ixz="0" iyy="0.01" iyz="0" izz="0.1" />
        </inertial>
    </link>


    <joint name="joint4" type="revolute">
        <parent link="link_3"/>
        <child link="link_4"/>
        <origin xyz="0 -0.075 0.55" rpy="0.0 0.0 0.0"/>
        <axis xyz="0 1 0"/>
        <limit lower="-2.62" upper="2.62" effort="30.0" velocity="3.14"/>
    </joint>


    <link name="link_5">
        <visual>
            <geometry>
                <cylinder length="0.4" radius="0.05"/>
            </geometry>
            <origin rpy="0 0 0" xyz="0 0 0.2"/>
            <material name="blue"/>
        </visual>
        <collision>
            <geometry>
                <cylinder length="0.4" radius="0.05"/>
            </geometry>
            <origin rpy="0 0 0" xyz="0 0 0.2"/>
        </collision>
        <inertial>
            <origin rpy="0 0 0" xyz="0 0 0.2"/>
            <mass value="10"/>
            <inertia ixx="0.01"  ixy="0"  ixz="0" iyy="0.01" iyz="0" izz="0.1" />
        </inertial>
    </link>


    <joint name="joint_5" type="revolute">
        <parent link="link_4"/>
        <child link="link_5"/>
        <origin xyz="0 -0.05 0.05" rpy="0.0 0.0 0.0"/>
        <axis xyz="0 0 1"/>
        <limit lower="-3.14" upper="3.14" effort="50.0" velocity="3.14"/>
    </joint>


    <link name="link_6">
        <visual>
            <geometry>
                <cylinder length="0.1" radius="0.05"/>
            </geometry>
            <origin rpy="0 0 0" xyz="0 0.05 0"/>
            <material name="gray"/>
        </visual>
        <collision>
            <geometry>
                <cylinder length="0.1" radius="0.05"/>
            </geometry>
            <origin rpy="0 0 0" xyz="0 0.05 0"/>
        </collision>
        <inertial>
            <origin rpy="0 0 0" xyz="0 0.05 0"/>
            <mass value="10"/>
            <inertia ixx="0.01"  ixy="0"  ixz="0" iyy="0.01" iyz="0" izz="0.1" />
        </inertial>
    </link>


    <joint name="joint_6" type="revolute">
        <parent link="link_5"/>
        <child link="link_6"/>
        <origin xyz="0 0.05 0.35" rpy="0.0 0.0 0.0"/>
        <axis xyz="0 1 0"/>
        <limit lower="-2.62" upper="2.62" effort="30.0" velocity="3.14"/>
    </joint>


    <link name="link_7">
        <visual>
            <geometry>
                <cylinder length="0.05" radius="0.05"/>
            </geometry>
            <origin rpy="0 0 0" xyz="0 0 0.025"/>
            <material name="blue"/>
        </visual>
        <collision>
            <geometry>
                <cylinder length="0.05" radius="0.05"/>
            </geometry>
            <origin rpy="0 0 0" xyz="0 0 0.025"/>
        </collision>
        <inertial>
            <origin rpy="0 0 0" xyz="0 0 0.025"/>
            <mass value="10"/>
            <inertia ixx="0.01"  ixy="0"  ixz="0" iyy="0.01" iyz="0" izz="0.1" />
        </inertial>
    </link>


    <joint name="joint_7" type="revolute">
        <parent link="link_6"/>
        <child link="link_7"/>
        <origin xyz="0 0.05 0.05" rpy="0.0 0.0 0.0"/>
        <axis xyz="0 0 1"/>
        <limit lower="-3.14" upper="3.14" effort="30.0" velocity="3.14"/>
    </joint>


    <link name="hand_base">
        <visual>
            <geometry>
                <box size="0.02 0.2 0.04"/>
            </geometry>
            <origin rpy="0 0 0" xyz="0 0 0.02"/>
            <material name="gray"/>
        </visual>
        <collision>
            <geometry>
                <box size="0.02 0.2 0.04"/>
            </geometry>
            <origin rpy="0 0 0" xyz="0 0 0.02"/>
        </collision>
        <inertial>
            <origin rpy="0 0 0" xyz="0 0 0.025"/>
            <mass value="0.5"/>
            <inertia ixx="0.00173"  ixy="0"  ixz="0" iyy="0.0000833" iyz="0" izz="0.00168" />
        </inertial>
    </link>


    <joint name="joint_link_7_to_hand_base" type="fixed">
        <parent link="link_7"/>
        <child link="hand_base"/>
        <origin xyz="0 0 0.05" rpy="0.0 0.0 0.0"/>
    </joint>


    <link name="left_finger">
        <visual>
            <geometry>
                <box size="0.02 0.01 0.08"/>
            </geometry>
            <origin rpy="0 0 0" xyz="0 0 0.04"/>
            <material name="gray"/>
        </visual>
        <collision>
            <geometry>
                <box size="0.02 0.01 0.08"/>
            </geometry>
            <origin rpy="0 0 0" xyz="0 0 0.04"/>
        </collision>
        <inertial>
            <origin rpy="0 0 0" xyz="0 0 0.04"/>
            <mass value="0.5"/>
            <inertia ixx="0.0000536"  ixy="0"  ixz="0" iyy="0.0000566" iyz="0" izz="0.00000354" />
        </inertial>
    </link>


    <joint name="joint_hand_base_to_left_finger" type="prismatic">
        <parent link="hand_base"/>
        <child link="left_finger"/>
        <origin xyz="0 -0.095 0.04" rpy="0.0 0.0 0.0"/>
        <axis xyz="0 1 0"/>
        <limit lower="0.0" upper="0.099" effort="30.0" velocity="0.1"/>
    </joint>


    <link name="right_finger">
        <visual>
            <geometry>
                <box size="0.02 0.01 0.08"/>
            </geometry>
            <origin rpy="0 0 0" xyz="0 0 0.04"/>
            <material name="gray"/>
        </visual>
        <collision>
            <geometry>
                <box size="0.02 0.01 0.08"/>
            </geometry>
            <origin rpy="0 0 0" xyz="0 0 0.04"/>
        </collision>
        <inertial>
            <origin rpy="0 0 0" xyz="0 0 0.04"/>
            <mass value="0.5"/>
            <inertia ixx="0.000268"  ixy="0"  ixz="0" iyy="0.000283" iyz="0" izz="0.0000177" />
        </inertial>
    </link>


    <joint name="joint_hand_base_to_right_finger" type="prismatic">
        <parent link="hand_base"/>
        <child link="right_finger"/>
        <origin xyz="0 0.095 0.04" rpy="0.0 0.0 3.14"/>
        <axis xyz="0 1 0"/>
        <limit lower="0.0" upper="0.099" effort="30.0" velocity="0.1"/>
        <mimic joint="joint_hand_base_to_left_finger" multiplier="1.0" offset="0"/>
    </joint>


    <link name="tcp" />

    <joint name="joint_hand_base_to_tcp" type="fixed">
        <parent link="hand_base"/>
        <child link="tcp"/>
        <origin xyz="0 0.0 0.12" rpy="0.0 0.0 1.57"/>
    </joint>

</robot>
